[2023-11-04 14:17:51,619] {taskinstance.py:1037} INFO - Dependencies all met for <TaskInstance: people-schema.init scheduled__2023-07-01T00:00:00+00:00 [queued]>
[2023-11-04 14:17:51,631] {taskinstance.py:1037} INFO - Dependencies all met for <TaskInstance: people-schema.init scheduled__2023-07-01T00:00:00+00:00 [queued]>
[2023-11-04 14:17:51,633] {taskinstance.py:1243} INFO - 
--------------------------------------------------------------------------------
[2023-11-04 14:17:51,633] {taskinstance.py:1244} INFO - Starting attempt 1 of 1
[2023-11-04 14:17:51,634] {taskinstance.py:1245} INFO - 
--------------------------------------------------------------------------------
[2023-11-04 14:17:51,647] {taskinstance.py:1264} INFO - Executing <Task(PythonOperator): init> on 2023-07-01 00:00:00+00:00
[2023-11-04 14:17:51,652] {standard_task_runner.py:52} INFO - Started process 268 to run task
[2023-11-04 14:17:51,658] {standard_task_runner.py:76} INFO - Running: ['***', 'tasks', 'run', 'people-schema', 'init', 'scheduled__2023-07-01T00:00:00+00:00', '--job-id', '9', '--raw', '--subdir', 'DAGS_FOLDER/people-schema.py', '--cfg-path', '/tmp/tmpqm_4dg2y', '--error-file', '/tmp/tmpsj67u946']
[2023-11-04 14:17:51,659] {standard_task_runner.py:77} INFO - Job 9: Subtask init
[2023-11-04 14:17:51,730] {logging_mixin.py:109} INFO - Running <TaskInstance: people-schema.init scheduled__2023-07-01T00:00:00+00:00 [running]> on host f5a9780aa73a
[2023-11-04 14:17:51,803] {taskinstance.py:1429} INFO - Exporting the following env vars:
AIRFLOW_CTX_DAG_OWNER=***
AIRFLOW_CTX_DAG_ID=people-schema
AIRFLOW_CTX_TASK_ID=init
AIRFLOW_CTX_EXECUTION_DATE=2023-07-01T00:00:00+00:00
AIRFLOW_CTX_DAG_RUN_ID=scheduled__2023-07-01T00:00:00+00:00
[2023-11-04 14:17:51,832] {taskinstance.py:1718} ERROR - Task failed with exception
Traceback (most recent call last):
  File "/home/airflow/.local/lib/python3.8/site-packages/airflow/models/taskinstance.py", line 1334, in _run_raw_task
    self._execute_task_with_callbacks(context)
  File "/home/airflow/.local/lib/python3.8/site-packages/airflow/models/taskinstance.py", line 1460, in _execute_task_with_callbacks
    result = self._execute_task(context, self.task)
  File "/home/airflow/.local/lib/python3.8/site-packages/airflow/models/taskinstance.py", line 1516, in _execute_task
    result = execute_callable(context=context)
  File "/home/airflow/.local/lib/python3.8/site-packages/airflow/operators/python.py", line 174, in execute
    return_value = self.execute_callable()
  File "/home/airflow/.local/lib/python3.8/site-packages/airflow/operators/python.py", line 188, in execute_callable
    return self.python_callable(*self.op_args, **self.op_kwargs)
  File "/opt/airflow/dags/people-schema.py", line 15, in init_schema
    db_engine = db_hook.get_sqlalchemy_engine()
  File "/home/airflow/.local/lib/python3.8/site-packages/airflow/hooks/dbapi.py", line 118, in get_sqlalchemy_engine
    return create_engine(self.get_uri(), **engine_kwargs)
  File "/home/airflow/.local/lib/python3.8/site-packages/airflow/providers/postgres/hooks/postgres.py", line 144, in get_uri
    uri = super().get_uri().replace("postgres://", "postgresql://")
  File "/home/airflow/.local/lib/python3.8/site-packages/airflow/hooks/dbapi.py", line 99, in get_uri
    conn = self.get_connection(getattr(self, self.conn_name_attr))
  File "/home/airflow/.local/lib/python3.8/site-packages/airflow/hooks/base.py", line 68, in get_connection
    conn = Connection.get_connection_from_secrets(conn_id)
  File "/home/airflow/.local/lib/python3.8/site-packages/airflow/models/connection.py", line 410, in get_connection_from_secrets
    raise AirflowNotFoundException(f"The conn_id `{conn_id}` isn't defined")
airflow.exceptions.AirflowNotFoundException: The conn_id `test_conn` isn't defined
[2023-11-04 14:17:51,844] {taskinstance.py:1272} INFO - Marking task as FAILED. dag_id=people-schema, task_id=init, execution_date=20230701T000000, start_date=20231104T141751, end_date=20231104T141751
[2023-11-04 14:17:51,861] {standard_task_runner.py:89} ERROR - Failed to execute job 9 for task init
Traceback (most recent call last):
  File "/home/airflow/.local/lib/python3.8/site-packages/airflow/task/task_runner/standard_task_runner.py", line 85, in _start_by_fork
    args.func(args, dag=self.dag)
  File "/home/airflow/.local/lib/python3.8/site-packages/airflow/cli/cli_parser.py", line 48, in command
    return func(*args, **kwargs)
  File "/home/airflow/.local/lib/python3.8/site-packages/airflow/utils/cli.py", line 92, in wrapper
    return f(*args, **kwargs)
  File "/home/airflow/.local/lib/python3.8/site-packages/airflow/cli/commands/task_command.py", line 298, in task_run
    _run_task_by_selected_method(args, dag, ti)
  File "/home/airflow/.local/lib/python3.8/site-packages/airflow/cli/commands/task_command.py", line 107, in _run_task_by_selected_method
    _run_raw_task(args, ti)
  File "/home/airflow/.local/lib/python3.8/site-packages/airflow/cli/commands/task_command.py", line 180, in _run_raw_task
    ti._run_raw_task(
  File "/home/airflow/.local/lib/python3.8/site-packages/airflow/utils/session.py", line 70, in wrapper
    return func(*args, session=session, **kwargs)
  File "/home/airflow/.local/lib/python3.8/site-packages/airflow/models/taskinstance.py", line 1334, in _run_raw_task
    self._execute_task_with_callbacks(context)
  File "/home/airflow/.local/lib/python3.8/site-packages/airflow/models/taskinstance.py", line 1460, in _execute_task_with_callbacks
    result = self._execute_task(context, self.task)
  File "/home/airflow/.local/lib/python3.8/site-packages/airflow/models/taskinstance.py", line 1516, in _execute_task
    result = execute_callable(context=context)
  File "/home/airflow/.local/lib/python3.8/site-packages/airflow/operators/python.py", line 174, in execute
    return_value = self.execute_callable()
  File "/home/airflow/.local/lib/python3.8/site-packages/airflow/operators/python.py", line 188, in execute_callable
    return self.python_callable(*self.op_args, **self.op_kwargs)
  File "/opt/airflow/dags/people-schema.py", line 15, in init_schema
    db_engine = db_hook.get_sqlalchemy_engine()
  File "/home/airflow/.local/lib/python3.8/site-packages/airflow/hooks/dbapi.py", line 118, in get_sqlalchemy_engine
    return create_engine(self.get_uri(), **engine_kwargs)
  File "/home/airflow/.local/lib/python3.8/site-packages/airflow/providers/postgres/hooks/postgres.py", line 144, in get_uri
    uri = super().get_uri().replace("postgres://", "postgresql://")
  File "/home/airflow/.local/lib/python3.8/site-packages/airflow/hooks/dbapi.py", line 99, in get_uri
    conn = self.get_connection(getattr(self, self.conn_name_attr))
  File "/home/airflow/.local/lib/python3.8/site-packages/airflow/hooks/base.py", line 68, in get_connection
    conn = Connection.get_connection_from_secrets(conn_id)
  File "/home/airflow/.local/lib/python3.8/site-packages/airflow/models/connection.py", line 410, in get_connection_from_secrets
    raise AirflowNotFoundException(f"The conn_id `{conn_id}` isn't defined")
airflow.exceptions.AirflowNotFoundException: The conn_id `test_conn` isn't defined
[2023-11-04 14:17:51,912] {local_task_job.py:154} INFO - Task exited with return code 1
[2023-11-04 14:17:51,963] {local_task_job.py:264} INFO - 0 downstream tasks scheduled from follow-on schedule check
