[2023-11-04 14:19:11,437] {taskinstance.py:1037} INFO - Dependencies all met for <TaskInstance: people-schema.init scheduled__2023-07-01T00:00:00+00:00 [failed]>
[2023-11-04 14:19:11,449] {taskinstance.py:1037} INFO - Dependencies all met for <TaskInstance: people-schema.init scheduled__2023-07-01T00:00:00+00:00 [failed]>
[2023-11-04 14:19:11,450] {taskinstance.py:1243} INFO - 
--------------------------------------------------------------------------------
[2023-11-04 14:19:11,451] {taskinstance.py:1244} INFO - Starting attempt 2 of 1
[2023-11-04 14:19:11,452] {taskinstance.py:1245} INFO - 
--------------------------------------------------------------------------------
[2023-11-04 14:19:11,461] {taskinstance.py:1264} INFO - Executing <Task(PythonOperator): init> on 2023-07-01 00:00:00+00:00
[2023-11-04 14:19:11,466] {standard_task_runner.py:52} INFO - Started process 318 to run task
[2023-11-04 14:19:11,472] {standard_task_runner.py:76} INFO - Running: ['***', 'tasks', 'run', 'people-schema', 'init', 'scheduled__2023-07-01T00:00:00+00:00', '--job-id', '10', '--pool', 'default_pool', '--raw', '--subdir', 'DAGS_FOLDER/people-schema.py', '--cfg-path', '/tmp/tmpzuw_lzsz', '--error-file', '/tmp/tmplkiksj12']
[2023-11-04 14:19:11,473] {standard_task_runner.py:77} INFO - Job 10: Subtask init
[2023-11-04 14:19:11,573] {logging_mixin.py:109} INFO - Running <TaskInstance: people-schema.init scheduled__2023-07-01T00:00:00+00:00 [running]> on host f5a9780aa73a
[2023-11-04 14:19:11,654] {taskinstance.py:1429} INFO - Exporting the following env vars:
AIRFLOW_CTX_DAG_OWNER=***
AIRFLOW_CTX_DAG_ID=people-schema
AIRFLOW_CTX_TASK_ID=init
AIRFLOW_CTX_EXECUTION_DATE=2023-07-01T00:00:00+00:00
AIRFLOW_CTX_DAG_RUN_ID=scheduled__2023-07-01T00:00:00+00:00
[2023-11-04 14:19:11,671] {base.py:70} INFO - Using connection to: id: test_conn. Host: host.docker.internal, Port: 15432, Schema: , Login: ***, Password: ***, extra: {}
[2023-11-04 14:19:11,682] {base.py:70} INFO - Using connection to: id: test_conn. Host: host.docker.internal, Port: 15432, Schema: , Login: ***, Password: ***, extra: {}
[2023-11-04 14:19:11,771] {taskinstance.py:1718} ERROR - Task failed with exception
Traceback (most recent call last):
  File "/home/airflow/.local/lib/python3.8/site-packages/sqlalchemy/engine/base.py", line 1276, in _execute_context
    self.dialect.do_execute(
  File "/home/airflow/.local/lib/python3.8/site-packages/sqlalchemy/engine/default.py", line 608, in do_execute
    cursor.execute(statement, parameters)
psycopg2.errors.InvalidSchemaName: schema "test" does not exist
LINE 2: CREATE TABLE test.people (
                     ^


The above exception was the direct cause of the following exception:

Traceback (most recent call last):
  File "/home/airflow/.local/lib/python3.8/site-packages/airflow/models/taskinstance.py", line 1334, in _run_raw_task
    self._execute_task_with_callbacks(context)
  File "/home/airflow/.local/lib/python3.8/site-packages/airflow/models/taskinstance.py", line 1460, in _execute_task_with_callbacks
    result = self._execute_task(context, self.task)
  File "/home/airflow/.local/lib/python3.8/site-packages/airflow/models/taskinstance.py", line 1516, in _execute_task
    result = execute_callable(context=context)
  File "/home/airflow/.local/lib/python3.8/site-packages/airflow/operators/python.py", line 174, in execute
    return_value = self.execute_callable()
  File "/home/airflow/.local/lib/python3.8/site-packages/airflow/operators/python.py", line 188, in execute_callable
    return self.python_callable(*self.op_args, **self.op_kwargs)
  File "/opt/airflow/dags/people-schema.py", line 37, in init_schema
    People.metadata.create_all(bind=db_engine)
  File "/home/airflow/.local/lib/python3.8/site-packages/sqlalchemy/sql/schema.py", line 4664, in create_all
    bind._run_visitor(
  File "/home/airflow/.local/lib/python3.8/site-packages/sqlalchemy/engine/base.py", line 2095, in _run_visitor
    conn._run_visitor(visitorcallable, element, **kwargs)
  File "/home/airflow/.local/lib/python3.8/site-packages/sqlalchemy/engine/base.py", line 1656, in _run_visitor
    visitorcallable(self.dialect, self, **kwargs).traverse_single(element)
  File "/home/airflow/.local/lib/python3.8/site-packages/sqlalchemy/sql/visitors.py", line 145, in traverse_single
    return meth(obj, **kw)
  File "/home/airflow/.local/lib/python3.8/site-packages/sqlalchemy/sql/ddl.py", line 783, in visit_metadata
    self.traverse_single(
  File "/home/airflow/.local/lib/python3.8/site-packages/sqlalchemy/sql/visitors.py", line 145, in traverse_single
    return meth(obj, **kw)
  File "/home/airflow/.local/lib/python3.8/site-packages/sqlalchemy/sql/ddl.py", line 827, in visit_table
    self.connection.execute(
  File "/home/airflow/.local/lib/python3.8/site-packages/sqlalchemy/engine/base.py", line 1011, in execute
    return meth(self, multiparams, params)
  File "/home/airflow/.local/lib/python3.8/site-packages/sqlalchemy/sql/ddl.py", line 72, in _execute_on_connection
    return connection._execute_ddl(self, multiparams, params)
  File "/home/airflow/.local/lib/python3.8/site-packages/sqlalchemy/engine/base.py", line 1068, in _execute_ddl
    ret = self._execute_context(
  File "/home/airflow/.local/lib/python3.8/site-packages/sqlalchemy/engine/base.py", line 1316, in _execute_context
    self._handle_dbapi_exception(
  File "/home/airflow/.local/lib/python3.8/site-packages/sqlalchemy/engine/base.py", line 1510, in _handle_dbapi_exception
    util.raise_(
  File "/home/airflow/.local/lib/python3.8/site-packages/sqlalchemy/util/compat.py", line 182, in raise_
    raise exception
  File "/home/airflow/.local/lib/python3.8/site-packages/sqlalchemy/engine/base.py", line 1276, in _execute_context
    self.dialect.do_execute(
  File "/home/airflow/.local/lib/python3.8/site-packages/sqlalchemy/engine/default.py", line 608, in do_execute
    cursor.execute(statement, parameters)
sqlalchemy.exc.ProgrammingError: (psycopg2.errors.InvalidSchemaName) schema "test" does not exist
LINE 2: CREATE TABLE test.people (
                     ^

[SQL: 
CREATE TABLE test.people (
	id SERIAL NOT NULL, 
	surname VARCHAR, 
	name VARCHAR, 
	middle_name VARCHAR, 
	agreement BYTEA, 
	PRIMARY KEY (id), 
	CONSTRAINT uix_sur_name_middle UNIQUE (surname, middle_name)
)

]
(Background on this error at: http://sqlalche.me/e/13/f405)
[2023-11-04 14:19:11,793] {taskinstance.py:1272} INFO - Marking task as FAILED. dag_id=people-schema, task_id=init, execution_date=20230701T000000, start_date=20231104T141911, end_date=20231104T141911
[2023-11-04 14:19:11,808] {standard_task_runner.py:89} ERROR - Failed to execute job 10 for task init
Traceback (most recent call last):
  File "/home/airflow/.local/lib/python3.8/site-packages/sqlalchemy/engine/base.py", line 1276, in _execute_context
    self.dialect.do_execute(
  File "/home/airflow/.local/lib/python3.8/site-packages/sqlalchemy/engine/default.py", line 608, in do_execute
    cursor.execute(statement, parameters)
psycopg2.errors.InvalidSchemaName: schema "test" does not exist
LINE 2: CREATE TABLE test.people (
                     ^


The above exception was the direct cause of the following exception:

Traceback (most recent call last):
  File "/home/airflow/.local/lib/python3.8/site-packages/airflow/task/task_runner/standard_task_runner.py", line 85, in _start_by_fork
    args.func(args, dag=self.dag)
  File "/home/airflow/.local/lib/python3.8/site-packages/airflow/cli/cli_parser.py", line 48, in command
    return func(*args, **kwargs)
  File "/home/airflow/.local/lib/python3.8/site-packages/airflow/utils/cli.py", line 92, in wrapper
    return f(*args, **kwargs)
  File "/home/airflow/.local/lib/python3.8/site-packages/airflow/cli/commands/task_command.py", line 298, in task_run
    _run_task_by_selected_method(args, dag, ti)
  File "/home/airflow/.local/lib/python3.8/site-packages/airflow/cli/commands/task_command.py", line 107, in _run_task_by_selected_method
    _run_raw_task(args, ti)
  File "/home/airflow/.local/lib/python3.8/site-packages/airflow/cli/commands/task_command.py", line 180, in _run_raw_task
    ti._run_raw_task(
  File "/home/airflow/.local/lib/python3.8/site-packages/airflow/utils/session.py", line 70, in wrapper
    return func(*args, session=session, **kwargs)
  File "/home/airflow/.local/lib/python3.8/site-packages/airflow/models/taskinstance.py", line 1334, in _run_raw_task
    self._execute_task_with_callbacks(context)
  File "/home/airflow/.local/lib/python3.8/site-packages/airflow/models/taskinstance.py", line 1460, in _execute_task_with_callbacks
    result = self._execute_task(context, self.task)
  File "/home/airflow/.local/lib/python3.8/site-packages/airflow/models/taskinstance.py", line 1516, in _execute_task
    result = execute_callable(context=context)
  File "/home/airflow/.local/lib/python3.8/site-packages/airflow/operators/python.py", line 174, in execute
    return_value = self.execute_callable()
  File "/home/airflow/.local/lib/python3.8/site-packages/airflow/operators/python.py", line 188, in execute_callable
    return self.python_callable(*self.op_args, **self.op_kwargs)
  File "/opt/airflow/dags/people-schema.py", line 37, in init_schema
    People.metadata.create_all(bind=db_engine)
  File "/home/airflow/.local/lib/python3.8/site-packages/sqlalchemy/sql/schema.py", line 4664, in create_all
    bind._run_visitor(
  File "/home/airflow/.local/lib/python3.8/site-packages/sqlalchemy/engine/base.py", line 2095, in _run_visitor
    conn._run_visitor(visitorcallable, element, **kwargs)
  File "/home/airflow/.local/lib/python3.8/site-packages/sqlalchemy/engine/base.py", line 1656, in _run_visitor
    visitorcallable(self.dialect, self, **kwargs).traverse_single(element)
  File "/home/airflow/.local/lib/python3.8/site-packages/sqlalchemy/sql/visitors.py", line 145, in traverse_single
    return meth(obj, **kw)
  File "/home/airflow/.local/lib/python3.8/site-packages/sqlalchemy/sql/ddl.py", line 783, in visit_metadata
    self.traverse_single(
  File "/home/airflow/.local/lib/python3.8/site-packages/sqlalchemy/sql/visitors.py", line 145, in traverse_single
    return meth(obj, **kw)
  File "/home/airflow/.local/lib/python3.8/site-packages/sqlalchemy/sql/ddl.py", line 827, in visit_table
    self.connection.execute(
  File "/home/airflow/.local/lib/python3.8/site-packages/sqlalchemy/engine/base.py", line 1011, in execute
    return meth(self, multiparams, params)
  File "/home/airflow/.local/lib/python3.8/site-packages/sqlalchemy/sql/ddl.py", line 72, in _execute_on_connection
    return connection._execute_ddl(self, multiparams, params)
  File "/home/airflow/.local/lib/python3.8/site-packages/sqlalchemy/engine/base.py", line 1068, in _execute_ddl
    ret = self._execute_context(
  File "/home/airflow/.local/lib/python3.8/site-packages/sqlalchemy/engine/base.py", line 1316, in _execute_context
    self._handle_dbapi_exception(
  File "/home/airflow/.local/lib/python3.8/site-packages/sqlalchemy/engine/base.py", line 1510, in _handle_dbapi_exception
    util.raise_(
  File "/home/airflow/.local/lib/python3.8/site-packages/sqlalchemy/util/compat.py", line 182, in raise_
    raise exception
  File "/home/airflow/.local/lib/python3.8/site-packages/sqlalchemy/engine/base.py", line 1276, in _execute_context
    self.dialect.do_execute(
  File "/home/airflow/.local/lib/python3.8/site-packages/sqlalchemy/engine/default.py", line 608, in do_execute
    cursor.execute(statement, parameters)
sqlalchemy.exc.ProgrammingError: (psycopg2.errors.InvalidSchemaName) schema "test" does not exist
LINE 2: CREATE TABLE test.people (
                     ^

[SQL: 
CREATE TABLE test.people (
	id SERIAL NOT NULL, 
	surname VARCHAR, 
	name VARCHAR, 
	middle_name VARCHAR, 
	agreement BYTEA, 
	PRIMARY KEY (id), 
	CONSTRAINT uix_sur_name_middle UNIQUE (surname, middle_name)
)

]
(Background on this error at: http://sqlalche.me/e/13/f405)
[2023-11-04 14:19:11,846] {local_task_job.py:154} INFO - Task exited with return code 1
[2023-11-04 14:19:11,883] {local_task_job.py:264} INFO - 0 downstream tasks scheduled from follow-on schedule check
